someidaisuke@someidaisukenoMacBook-Pro google_weak_keyword_search % python -u "/Users/someidaisuke/Desktop/Python_tutorial/google_weak_keyword_search/google_weak_keyword_search_copy.py"
Traceback (most recent call last):
  File "/Users/someidaisuke/Desktop/Python_tutorial/google_weak_keyword_search/google_weak_keyword_search_copy.py", line 34, in <module>
    driver=webdriver.Chrome(options=options)
  File "/Users/someidaisuke/.pyenv/versions/3.8.10/lib/python3.8/site-packages/selenium/webdriver/chrome/webdriver.py", line 76, in __init__
    RemoteWebDriver.__init__(
  File "/Users/someidaisuke/.pyenv/versions/3.8.10/lib/python3.8/site-packages/selenium/webdriver/remote/webdriver.py", line 157, in __init__
    self.start_session(capabilities, browser_profile)
  File "/Users/someidaisuke/.pyenv/versions/3.8.10/lib/python3.8/site-packages/selenium/webdriver/remote/webdriver.py", line 252, in start_session
    response = self.execute(Command.NEW_SESSION, parameters)
  File "/Users/someidaisuke/.pyenv/versions/3.8.10/lib/python3.8/site-packages/selenium/webdriver/remote/webdriver.py", line 319, in execute
    response = self.command_executor.execute(driver_command, params)
  File "/Users/someidaisuke/.pyenv/versions/3.8.10/lib/python3.8/site-packages/selenium/webdriver/remote/remote_connection.py", line 374, in execute
    return self._request(command_info[0], url, body=data)
  File "/Users/someidaisuke/.pyenv/versions/3.8.10/lib/python3.8/site-packages/selenium/webdriver/remote/remote_connection.py", line 397, in _request
    resp = self._conn.request(method, url, body=body, headers=headers)
  File "/Users/someidaisuke/.pyenv/versions/3.8.10/lib/python3.8/site-packages/urllib3/_request_methods.py", line 144, in request
    return self.request_encode_body(
  File "/Users/someidaisuke/.pyenv/versions/3.8.10/lib/python3.8/site-packages/urllib3/_request_methods.py", line 279, in request_encode_body
    return self.urlopen(method, url, **extra_kw)
  File "/Users/someidaisuke/.pyenv/versions/3.8.10/lib/python3.8/site-packages/urllib3/poolmanager.py", line 433, in urlopen
    conn = self.connection_from_host(u.host, port=u.port, scheme=u.scheme)
  File "/Users/someidaisuke/.pyenv/versions/3.8.10/lib/python3.8/site-packages/urllib3/poolmanager.py", line 304, in connection_from_host
    return self.connection_from_context(request_context)
  File "/Users/someidaisuke/.pyenv/versions/3.8.10/lib/python3.8/site-packages/urllib3/poolmanager.py", line 329, in connection_from_context
    return self.connection_from_pool_key(pool_key, request_context=request_context)
  File "/Users/someidaisuke/.pyenv/versions/3.8.10/lib/python3.8/site-packages/urllib3/poolmanager.py", line 352, in connection_from_pool_key
    pool = self._new_pool(scheme, host, port, request_context=request_context)
  File "/Users/someidaisuke/.pyenv/versions/3.8.10/lib/python3.8/site-packages/urllib3/poolmanager.py", line 266, in _new_pool
    return pool_cls(host, port, **request_context)
  File "/Users/someidaisuke/.pyenv/versions/3.8.10/lib/python3.8/site-packages/urllib3/connectionpool.py", line 196, in __init__
    timeout = Timeout.from_float(timeout)
  File "/Users/someidaisuke/.pyenv/versions/3.8.10/lib/python3.8/site-packages/urllib3/util/timeout.py", line 186, in from_float
    return Timeout(read=timeout, connect=timeout)
  File "/Users/someidaisuke/.pyenv/versions/3.8.10/lib/python3.8/site-packages/urllib3/util/timeout.py", line 115, in __init__
    self._connect = self._validate_timeout(connect, "connect")
  File "/Users/someidaisuke/.pyenv/versions/3.8.10/lib/python3.8/site-packages/urllib3/util/timeout.py", line 152, in _validate_timeout
    raise ValueError(
ValueError: Timeout value connect was <object object at 0x100de4090>, but it must be an int, float or None.
